Workbook

Sheet Olinda
A1: Receitas Orçamentárias – Olinda/PE (2016–2025) | Valores em R$ | Fonte: SICONFI/STN
A2: Categoria | B2: 2016 | C2: 2017 | D2: 2018 | E2: 2019 | F2: 2020 | G2: 2021 | H2: 2022 | I2: 2023 | J2: 2024 | K2: 2025
A3: Total Receitas | B3: =B4+B11+B12 -> 6.2862434e+08 | C3: =C4+C11+C12 -> 6.2729211e+08 | D3: =D4+D11+D12 -> 6.8858178e+08 | E3: =E4+E11+E12 -> 7.2126639e+08 | F3: =F4+F11+F12 -> 7.8091407e+08 | G3: =G4+G11+G12 -> 8.374573e+08 | H3: =H4+H11+H12 -> 1.0319936e+09 | I3: =I4+I11+I12 -> 1.0887123e+09 | ... K3: =K4+K11+K12 -> 1.2467533e+09
A4: Receitas Correntes | B4: 5.8391598e+08 | C4: 596440830 | D4: 6.5609638e+08 | E4: 6.9313851e+08 | F4: 7.3182003e+08 | G4: 7.9573654e+08 | H4: 9.467518e+08 | I4: 1.0099642e+09 | J4: 1.1244793e+09 | K4: 1.1604348e+09
A5: Receita Tributária | B5: 1.1599067e+08 | C5: 1.2476644e+08 | D5: 1.4455587e+08 | E5: 1.6541112e+08 | F5: 1.4876839e+08 | G5: 1.6988253e+08 | H5: 2.1510041e+08 | I5: 2.4885679e+08 | J5: 2.8457897e+08 | K5: 2.949488e+08
A6: Contribuições | B6: 34054421 | C6: 33724900 | D6: 31988535 | E6: 32827989 | F6: 33547219 | G6: 36272507 | H6: 46023984 | I6: 55828259 | J6: 66334536 | K6: 72761352
A7: Rec. Patrimonial | B7: 18253162 | C7: 18288339 | D7: 18872238 | E7: 16282261 | F7: 19006882 | G7: 14253858 | H7: 30119936 | I7: 38400024 | J7: 32168442 | K7: 40905805
A8: Rec. de Serviços | B8: 113806.28 | C8: 142167.24 | D8: 304658.16 | E8: 150153.26 | F8: 50350.76 | G8: 81239.2 | H8: 123362.14 | I8: 3269988.1 | J8: 131996.61 | K8: 214218.07
A9: Transferências Correntes | B9: 4.0021859e+08 | C9: 4.0480482e+08 | D9: 4.3466184e+08 | E9: 4.703998e+08 | F9: 5.2410438e+08 | G9: 5.6292743e+08 | H9: 6.358524e+08 | I9: 6.4076751e+08 | J9: 7.015827e+08 | K9: 7.2300295e+08
A10: Outras Rec. Correntes | B10: 15285337 | C10: 14714170 | D10: 25713244 | E10: 8067191.9 | F10: 6342811.2 | G10: 12318968 | H10: 19531715 | I10: 22841604 | J10: 39682661 | K10: 28601670
A11: Rec. Intraorçamentárias | B11: 21207545 | C11: 21516952 | D11: 22453557 | E11: 22318742 | F11: 22076223 | G11: 25013975 | H11: 44031975 | I11: 52650805 | J11: 66050993 | K11: 63498359
A12: Receitas de Capital | B12: 23500807 | C12: 9334327.2 | D12: 10031837 | E12: 5809129.1 | F12: 27017821 | G12: 16706790 | H12: 41209859 | I12: 26097276 | J12: 40921942 | K12: 22820121
A13: Operações de Crédito | I13: 8000000 | J13: 28435196 | K13: 13379301
A14: Transferências de Capital | B14: 23500807 | C14: 9334327.2 | D14: 10031837 | E14: 5809129.1 | F14: 27017821 | G14: 16706790 | H14: 41209859 | I14: 18070280 | J14: 12451392 | K14: 8921795.6
A15: Amortização Empréstimos | I15: 26995.88 | J15: 35353.43 | K15: 1788.42
A17: Composição das Receitas Correntes (% do Total de Receitas Correntes)
A18: Categoria | B18: 2016 | C18: 2017 | D18: 2018 | E18: 2019 | F18: 2020 | G18: 2021 | H18: 2022 | I18: 2023 | J18: 2024 | K18: 2025
A19: Receita Tributária | B19: =B5/$B$4 -> 0.19864273 | C19: =C5/$C$4 -> 0.20918493 | D19: =D5/$D$4 -> 0.22032718 | E19: =E5/$E$4 -> 0.23864078 | F19: =F5/$F$4 -> 0.20328549 | G19: =G5/$G$4 -> 0.21349093 | H19: =H5/$H$4 -> 0.22719831 | I19: =I5/$I$4 -> 0.2464016 | J19: =J5/$J$4 -> 0.25307622 | K19: =K5/$K$4 -> 0.25417094
A20: Contribuições | B20: =B6/$B$4 -> 0.058320755 | C20: =C6/$C$4 -> 0.05654358 | D20: =D6/$D$4 -> 0.048755848 | E20: =E6/$E$4 -> 0.047361369 | F20: =F6/$F$4 -> 0.045840804 | G20: =G6/$G$4 -> 0.045583563 | H20: =H6/$H$4 -> 0.048612512 | I20: =I6/$I$4 -> 0.055277465 | J20: =J6/$J$4 -> 0.058991335 | K20: =K6/$K$4 -> 0.062701802
A21: Rec. Patrimonial | B21: =B7/$B$4 -> 0.031259912 | C21: =C7/$C$4 -> 0.030662453 | D21: =D7/$D$4 -> 0.028764429 | E21: =E7/$E$4 -> 0.02349063 | F21: =F7/$F$4 -> 0.025972071 | G21: =G7/$G$4 -> 0.017912785 | H21: =H7/$H$4 -> 0.031813972 | I21: =I7/$I$4 -> 0.038021174 | J21: =J7/$J$4 -> 0.028607411 | K21: =K7/$K$4 -> 0.035250412
A22: Rec. de Serviços | B22: =B8/$B$4 -> 0.00019490181 | C22: =C8/$C$4 -> 0.00023835934 | D22: =D8/$D$4 -> 0.0004643497 | E22: =E8/$E$4 -> 0.00021662807 | F22: =F8/$F$4 -> 6.8802107e-05 | G22: =G8/$G$4 -> 0.00010209309 | H22: =H8/$H$4 -> 0.0001303004 | I22: =I8/$I$4 -> 0.0032377269 | J22: =J8/$J$4 -> 0.00011738465 | K22: =K8/$K$4 -> 0.00018460156
A23: Transferências Correntes | B23: =B9/$B$4 -> 0.68540441 | C23: =C9/$C$4 -> 0.67870072 | D23: =D9/$D$4 -> 0.66249693 | E23: =E9/$E$4 -> 0.67865195 | F23: =F9/$F$4 -> 0.71616566 | G23: =G9/$G$4 -> 0.70742941 | H23: =H9/$H$4 -> 0.67161467 | I23: =I9/$I$4 -> 0.63444578 | J23: =J9/$J$4 -> 0.62391784 | K23: =K9/$K$4 -> 0.62304487
A24: Outras Rec. Correntes | B24: =B10/$B$4 -> 0.026177289 | C24: =C10/$C$4 -> 0.024669958 | D24: =D10/$D$4 -> 0.03919126 | E24: =E10/$E$4 -> 0.011638643 | F24: =F10/$F$4 -> 0.0086671735 | G24: =G10/$G$4 -> 0.015481214 | H24: =H10/$H$4 -> 0.020630238 | I24: =I10/$I$4 -> 0.022616252 | J24: =J10/$J$4 -> 0.03528981 | K24: =K10/$K$4 -> 0.024647374

Sheet Petrolina
B2: Receitas Orçamentárias – Petrolina/PE (2016–2025) | Valores em R$ | Fonte: SICONFI/STN
B3: Categoria | C3: 2016 | D3: 2017 | E3: 2018 | F3: 2019 | G3: 2020 | H3: 2021 | I3: 2022 | J3: 2023 | K3: 2024 | L3: 2025
B4: Total Receitas | C4: =C5+C12+C13 -> 6.4514674e+08 | D4: =D5+D12+D13 -> 6.6977918e+08 | E4: =E5+E12+E13 -> 7.5694838e+08 | F4: =F5+F12+F13 -> 8.4320416e+08 | G4: =G5+G12+G13 -> 9.6873914e+08 | H4: =H5+H12+H13 -> 1.1886012e+09 | I4: =I5+I12+I13 -> 1.3820829e+09 | J4: =J5+J12+J13 -> 1.6338802e+09 | ... L4: =L5+L12+L13 -> 1.9533483e+09
B5: Receitas Correntes | C5: 6.0618286e+08 | D5: 6.2668979e+08 | E5: 6.9427855e+08 | F5: 7.9798291e+08 | G5: 8.8109293e+08 | H5: 1.0462522e+09 | I5: 1.2736579e+09 | J5: 1.4413006e+09 | K5: 1.6223416e+09 | L5: 1.8173223e+09
B6: Receita Tributária | C6: 82409468 | D6: 89723913 | E6: 1.2082794e+08 | F6: 1.4388299e+08 | G6: 1.3837081e+08 | H6: 1.7786752e+08 | I6: 2.2885378e+08 | J6: 2.8319981e+08 | K6: 3.1614643e+08 | L6: 3.6108769e+08
B7: Contribuições | C7: 27768694 | D7: 29802247 | E7: 32738547 | F7: 18096484 | G7: 47342697 | H7: 59481669 | I7: 67666257 | J7: 74484270 | K7: 83104621 | L7: 81049029
B8: Rec. Patrimonial | C8: 14255111 | D8: 19993116 | E8: 16751882 | F8: 29739201 | G8: 25220129 | H8: 21132580 | I8: 54086124 | J8: 66088484 | K8: 77181918 | L8: 88448344
B9: Rec. de Serviços | C9: 22290113 | D9: 25200345 | E9: 25922719 | F9: 29384893 | G9: 24312927 | H9: 24499361 | I9: 29679969 | J9: 41843694 | K9: 44309475 | L9: 45190919
B10: Transferências Correntes | C10: 4.4619774e+08 | D10: 4.4778521e+08 | E10: 4.913181e+08 | F10: 5.5826527e+08 | G10: 6.4255235e+08 | H10: 7.567076e+08 | I10: 8.8472829e+08 | J10: 9.656658e+08 | K10: 1.0924262e+09 | L10: 1.2187729e+09
B11: Outras Rec. Correntes | C11: 13261732 | D11: 14184963 | E11: 6719351 | F11: 18614069 | G11: 3294018 | H11: 6563427.4 | I11: 8643510.7 | J11: 10018510 | K11: 9172982.4 | L11: 22773441
B12: Rec. Intraorçamentárias | C12: 25558268 | D12: 32148036 | E12: 29800870 | G12: 37466476 | H12: 58105558 | I12: 71181664 | J12: 78111814 | K12: 82902838 | L12: 78153425
B13: Receitas de Capital | C13: 13405607 | D13: 10941351 | E13: 32868966 | F13: 45221251 | G13: 50179735 | H13: 84243502 | I13: 37243300 | J13: 1.1446782e+08 | K13: 71397654 | L13: 57872584
B14: Operações de Crédito | C14: 5624613.8 | D14: 6246561.2 | E14: 12000000 | F14: 24000000 | G14: 26791521 | H14: 9941659.6 | I14: 2183235.1 | J14: 27535240 | K14: 25833333 | L14: 15666667
B15: Transferências de Capital | C15: 7309183.1 | D15: 4540178.8 | E15: 20499608 | F15: 20552023 | G15: 22839696 | H15: 73720908 | I15: 34431273 | J15: 86114684 | K15: 44233999 | L15: 34733558
B16: Amortização Empréstimos | C16: 471810.58 | D16: 154610.57 | E16: 369358.13 | F16: 669227.76 | G16: 548518.36 | H16: 580934.69 | I16: 628791.92 | J16: 817900.28 | K16: 1330322 | L16: 1472359.4
B18: Composição das Receitas Correntes (% do Total de Receitas Correntes)
B19: Categoria | C19: 2016 | D19: 2017 | E19: 2018 | F19: 2019 | G19: 2020 | H19: 2021 | I19: 2022 | J19: 2023 | K19: 2024 | L19: 2025
B20: Receita Tributária | C20: =C6/$C$5 -> 0.1359482 | D20: =D6/$D$5 -> 0.14317117 | E20: =E6/$E$5 -> 0.17403381 | F20: =F6/$F$5 -> 0.18030836 | G20: =G6/$G$5 -> 0.15704451 | H20: =H6/$H$5 -> 0.17000445 | I20: =I6/$I$5 -> 0.1796823 | J20: =J6/$J$5 -> 0.19648907 | K20: =K6/$K$5 -> 0.19487044 | L20: =L6/$L$5 -> 0.19869216
B21: Contribuições | C21: =C7/$C$5 -> 0.045809104 | D21: =D7/$D$5 -> 0.047555023 | E21: =E7/$E$5 -> 0.047154772 | F21: =F7/$F$5 -> 0.022677784 | G21: =G7/$G$5 -> 0.053731786 | H21: =H7/$H$5 -> 0.056852135 | I21: =I7/$I$5 -> 0.053127496 | J21: =J7/$J$5 -> 0.051678513 | K21: =K7/$K$5 -> 0.051225106 | L21: =L7/$L$5 -> 0.044598049
B22: Rec. Patrimonial | C22: =C8/$C$5 -> 0.02351619 | D22: =D8/$D$5 -> 0.031902731 | E22: =E8/$E$5 -> 0.024128474 | F22: =F8/$F$5 -> 0.037267967 | G22: =G8/$G$5 -> 0.028623688 | H22: =H8/$H$5 -> 0.020198363 | I22: =I8/$I$5 -> 0.042465188 | J22: =J8/$J$5 -> 0.045853367 | K22: =K8/$K$5 -> 0.047574394 | L22: =L8/$L$5 -> 0.048669597
B23: Rec. de Serviços | C23: =C9/$C$5 -> 0.036771268 | D23: =D9/$D$5 -> 0.040211833 | E23: =E9/$E$5 -> 0.037337636 | F23: =F9/$F$5 -> 0.036823963 | G23: =G9/$G$5 -> 0.027594055 | H23: =H9/$H$5 -> 0.023416307 | I23: =I9/$I$5 -> 0.023302936 | J23: =J9/$J$5 -> 0.0290319 | K23: =K9/$K$5 -> 0.02731205 | L23: =L9/$L$5 -> 0.024866761
B24: Transferências Correntes | C24: =C10/$C$5 -> 0.7360778 | D24: =D10/$D$5 -> 0.7145245 | E24: =E10/$E$5 -> 0.70766713 | F24: =F10/$F$5 -> 0.69959553 | G24: =G10/$G$5 -> 0.7292674 | H24: =H10/$H$5 -> 0.72325547 | I24: =I10/$I$5 -> 0.69463572 | J24: =J10/$J$5 -> 0.66999613 | K24: =K10/$K$5 -> 0.67336385 | L24: =L10/$L$5 -> 0.67064211
B25: Outras Rec. Correntes | C25: =C11/$C$5 -> 0.021877445 | D25: =D11/$D$5 -> 0.022634744 | E25: =E11/$E$5 -> 0.0096781775 | F25: =F11/$F$5 -> 0.0233264 | G25: =G11/$G$5 -> 0.0037385591 | H25: =H11/$H$5 -> 0.0062732749 | I25: =I11/$I$5 -> 0.0067863674 | J25: =J11/$J$5 -> 0.0069510204 | K25: =K11/$K$5 -> 0.0056541621 | L25: =L11/$L$5 -> 0.012531317

Sheet Comparativo e Evolução
A1: Comparativo de Receitas – Petrolina vs Olinda/PE (2016–2025) | Valores em R$ | Fonte: SICONFI/STN
A2: Categoria | B2: Município | C2: 2016 | D2: 2017 | E2: 2018 | F2: 2019 | G2: 2020 | H2: 2021 | I2: 2022 | J2: 2023 | K2: 2024 | L2: 2025
A3: Total Receitas | B3: Petrolina | C3: =Petrolina!C4 -> 6.4514674e+08 | D3: =Petrolina!D4 -> 6.6977918e+08 | E3: =Petrolina!E4 -> 7.5694838e+08 | F3: =Petrolina!F4 -> 8.4320416e+08 | G3: =Petrolina!G4 -> 9.6873914e+08 | H3: =Petrolina!H4 -> 1.1886012e+09 | I3: =Petrolina!I4 -> 1.3820829e+09 | J3: =Petrolina!J4 -> 1.6338802e+09 | ... L3: =Petrolina!L4 -> 1.9533483e+09
A4: Total Receitas | B4: Olinda | C4: =Olinda!B3 -> 6.2862434e+08 | D4: =Olinda!C3 -> 6.2729211e+08 | E4: =Olinda!D3 -> 6.8858178e+08 | F4: =Olinda!E3 -> 7.2126639e+08 | G4: =Olinda!F3 -> 7.8091407e+08 | H4: =Olinda!G3 -> 8.374573e+08 | I4: =Olinda!H3 -> 1.0319936e+09 | J4: =Olinda!I3 -> 1.0887123e+09 | ... L4: =Olinda!K3 -> 1.2467533e+09
A5: Receitas Correntes | B5: Petrolina | C5: =Petrolina!C5 -> 6.0618286e+08 | D5: =Petrolina!D5 -> 6.2668979e+08 | E5: =Petrolina!E5 -> 6.9427855e+08 | F5: =Petrolina!F5 -> 7.9798291e+08 | G5: =Petrolina!G5 -> 8.8109293e+08 | H5: =Petrolina!H5 -> 1.0462522e+09 | I5: =Petrolina!I5 -> 1.2736579e+09 | J5: =Petrolina!J5 -> 1.4413006e+09 | ... L5: =Petrolina!L5 -> 1.8173223e+09
A6: Receitas Correntes | B6: Olinda | C6: =Olinda!B4 -> 5.8391598e+08 | D6: =Olinda!C4 -> 596440830 | E6: =Olinda!D4 -> 6.5609638e+08 | F6: =Olinda!E4 -> 6.9313851e+08 | G6: =Olinda!F4 -> 7.3182003e+08 | H6: =Olinda!G4 -> 7.9573654e+08 | I6: =Olinda!H4 -> 9.467518e+08 | J6: =Olinda!I4 -> 1.0099642e+09 | ... L6: =Olinda!K4 -> 1.1604348e+09
A7: Receita Tributária | B7: Petrolina | C7: =Petrolina!C6 -> 82409468 | D7: =Petrolina!D6 -> 89723913 | E7: =Petrolina!E6 -> 1.2082794e+08 | F7: =Petrolina!F6 -> 1.4388299e+08 | G7: =Petrolina!G6 -> 1.3837081e+08 | H7: =Petrolina!H6 -> 1.7786752e+08 | I7: =Petrolina!I6 -> 2.2885378e+08 | J7: =Petrolina!J6 -> 2.8319981e+08 | ... L7: =Petrolina!L6 -> 3.6108769e+08
A8: Receita Tributária | B8: Olinda | C8: =Olinda!B5 -> 1.1599067e+08 | D8: =Olinda!C5 -> 1.2476644e+08 | E8: =Olinda!D5 -> 1.4455587e+08 | F8: =Olinda!E5 -> 1.6541112e+08 | G8: =Olinda!F5 -> 1.4876839e+08 | H8: =Olinda!G5 -> 1.6988253e+08 | I8: =Olinda!H5 -> 2.1510041e+08 | J8: =Olinda!I5 -> 2.4885679e+08 | ... L8: =Olinda!K5 -> 2.949488e+08
A9: Transferências Correntes | B9: Petrolina | C9: =Petrolina!C10 -> 4.4619774e+08 | D9: =Petrolina!D10 -> 4.4778521e+08 | E9: =Petrolina!E10 -> 4.913181e+08 | F9: =Petrolina!F10 -> 5.5826527e+08 | G9: =Petrolina!G10 -> 6.4255235e+08 | H9: =Petrolina!H10 -> 7.567076e+08 | I9: =Petrolina!I10 -> 8.8472829e+08 | J9: =Petrolina!J10 -> 9.656658e+08 | ... L9: =Petrolina!L10 -> 1.2187729e+09
A10: Transferências Correntes | B10: Olinda | C10: =Olinda!B9 -> 4.0021859e+08 | D10: =Olinda!C9 -> 4.0480482e+08 | E10: =Olinda!D9 -> 4.3466184e+08 | F10: =Olinda!E9 -> 4.703998e+08 | G10: =Olinda!F9 -> 5.2410438e+08 | H10: =Olinda!G9 -> 5.6292743e+08 | I10: =Olinda!H9 -> 6.358524e+08 | J10: =Olinda!I9 -> 6.4076751e+08 | ... L10: =Olinda!K9 -> 7.2300295e+08
A11: Receitas de Capital | B11: Petrolina | C11: =Petrolina!C13 -> 13405607 | D11: =Petrolina!D13 -> 10941351 | E11: =Petrolina!E13 -> 32868966 | F11: =Petrolina!F13 -> 45221251 | G11: =Petrolina!G13 -> 50179735 | H11: =Petrolina!H13 -> 84243502 | I11: =Petrolina!I13 -> 37243300 | J11: =Petrolina!J13 -> 1.1446782e+08 | ... L11: =Petrolina!L13 -> 57872584
A12: Receitas de Capital | B12: Olinda | C12: =Olinda!B12 -> 23500807 | D12: =Olinda!C12 -> 9334327.2 | E12: =Olinda!D12 -> 10031837 | F12: =Olinda!E12 -> 5809129.1 | G12: =Olinda!F12 -> 27017821 | H12: =Olinda!G12 -> 16706790 | I12: =Olinda!H12 -> 41209859 | J12: =Olinda!I12 -> 26097276 | ... L12: =Olinda!K12 -> 22820121
K14: DiNF
A15: Ano | B15: Petrolina – Total | C15: Olinda – Total
A16: 2016 | B16: 6.4514674e+08 | C16: 6.2862434e+08
A17: 2017 | B17: 6.6977918e+08 | C17: 6.2729211e+08
A18: 2018 | B18: 7.5694838e+08 | C18: 6.8858178e+08
A19: 2019 | B19: 8.4320416e+08 | C19: 7.2126639e+08
A20: 2020 | B20: 9.6873914e+08 | C20: 7.8091407e+08
A21: 2021 | B21: 1.1886012e+09 | C21: 8.374573e+08
A22: 2022 | B22: 1.3820829e+09 | C22: 1.0319936e+09
A23: 2023 | B23: 1.6338802e+09 | C23: 1.0887123e+09
A24: 2024 | B24: 1.7766421e+09 | C24: 1.2314522e+09
A25: 2025 | B25: 1.9533483e+09 | C25: 1.2467533e+09
A36: Categoria | B36: Receita Tributária | C36: Contribuições | D36: Rec. Patrimonial | E36: Rec. de Serviços | F36: Transferências Correntes | G36: Outras Rec. Correntes
A37: 2016 | B37: 82409468 | C37: 27768694 | D37: 14255111 | E37: 22290113 | F37: 4.4619774e+08 | G37: 13261732
A38: 2017 | B38: 89723913 | C38: 29802247 | D38: 19993116 | E38: 25200345 | F38: 4.4778521e+08 | G38: 14184963
A39: 2018 | B39: 1.2082794e+08 | C39: 32738547 | D39: 16751882 | E39: 25922719 | F39: 4.913181e+08 | G39: 6719351
A40: 2019 | B40: 1.4388299e+08 | C40: 18096484 | D40: 29739201 | E40: 29384893 | F40: 5.5826527e+08 | G40: 18614069
A41: 2020 | B41: 1.3837081e+08 | C41: 47342697 | D41: 25220129 | E41: 24312927 | F41: 6.4255235e+08 | G41: 3294018
A42: 2021 | B42: 1.7786752e+08 | C42: 59481669 | D42: 21132580 | E42: 24499361 | F42: 7.567076e+08 | G42: 6563427.4
A43: 2022 | B43: 2.2885378e+08 | C43: 67666257 | D43: 54086124 | E43: 29679969 | F43: 8.8472829e+08 | G43: 8643510.7
A44: 2023 | B44: 2.8319981e+08 | C44: 74484270 | D44: 66088484 | E44: 41843694 | F44: 9.656658e+08 | G44: 10018510
A45: 2024 | B45: 3.1614643e+08 | C45: 83104621 | D45: 77181918 | E45: 44309475 | F45: 1.0924262e+09 | G45: 9172982.4
A46: 2025 | B46: 3.6108769e+08 | C46: 81049029 | D46: 88448344 | E46: 45190919 | F46: 1.2187729e+09 | G46: 22773441
A61: Categoria | B61: Receita Tributária | C61: Contribuições | D61: Rec. Patrimonial | E61: Rec. de Serviços | F61: Transferências Correntes | G61: Outras Rec. Correntes
A62: 2016 | B62: 1.1599067e+08 | C62: 34054421 | D62: 18253162 | E62: 113806.28 | F62: 4.0021859e+08 | G62: 15285337
A63: 2017 | B63: 1.2476644e+08 | C63: 33724900 | D63: 18288339 | E63: 142167.24 | F63: 4.0480482e+08 | G63: 14714170
A64: 2018 | B64: 1.4455587e+08 | C64: 31988535 | D64: 18872238 | E64: 304658.16 | F64: 4.3466184e+08 | G64: 25713244
A65: 2019 | B65: 1.6541112e+08 | C65: 32827989 | D65: 16282261 | E65: 150153.26 | F65: 4.703998e+08 | G65: 8067191.9
...

Sheet Dados Brutos
A1: Receitas Orçamentárias – Petrolina/PE e Olinda/PE (2016–2025) | Fonte: SICONFI/STN
A2: Município | B2: Ano | C2: Código | D2: Descrição da Conta | E2: Coluna | F2: Valor (R$)
A3: Olinda | B3: 2016 | C3: 1.0.0.0.00.00.00 | D3: Receitas Correntes | E3: 1.0.0.0.00.00.00 - Receitas Correntes | F3: 5.8391598e+08
A4: Olinda | B4: 2016 | C4: 1.1.0.0.00.00.00 | D4: Receita Tributária | E4: 1.1.0.0.00.00.00 - Receita Tributária | F4: 1.1599067e+08
A5: Olinda | B5: 2016 | C5: 1.1.1.0.00.00.00 | D5: Impostos | E5: 1.1.1.0.00.00.00 - Impostos | F5: 95201232
A6: Olinda | B6: 2016 | C6: 1.1.1.2.00.00.00 | D6: Impostos sobre o Patrimônio e a Renda | E6: 1.1.1.2.00.00.00 - Impostos sobre o Patrimônio e a Renda | F6: 37900526
A7: Olinda | B7: 2016 | C7: 1.1.1.2.02.00.00 | D7: Imposto sobre a Propriedade Predial e Territorial Urbana ¿ IPTU | E7: 1.1.1.2.02.00.00 - Imposto sobre a Propriedade Predial e Territorial Urbana ¿ IPTU | F7: 19003054
A8: Olinda | B8: 2016 | C8: 1.1.1.2.04.00.00 | D8: Imposto sobre a Renda e Proventos de Qualquer Natureza ¿ IR | E8: 1.1.1.2.04.00.00 - Imposto sobre a Renda e Proventos de Qualquer Natureza ¿ IR | F8: 13628284
A9: Olinda | B9: 2016 | C9: 1.1.1.2.04.31.00 | D9: Retido nas Fontes - Trabalho | E9: 1.1.1.2.04.31.00 - Retido nas Fontes - Trabalho | F9: 8303933.6
A10: Olinda | B10: 2016 | C10: 1.1.1.2.04.34.00 | D10: Retido nas Fontes - Outros Rendimentos | E10: 1.1.1.2.04.34.00 - Retido nas Fontes - Outros Rendimentos | F10: 5324350.1
A11: Olinda | B11: 2016 | C11: 1.1.1.2.08.00.00 | D11: Imposto sobre Transmissão "Inter Vivos" de Bens Imóveis e de Direitos Reais sobre Imóveis ¿ ITBI | E11: 1.1.1.2.08.00.00 - Imposto sobre Transmissão "Inter Vivos" de Bens Imóveis e de Direitos Reais sobre Imóveis ¿ ITBI | F11: 5269188.5
A12: Olinda | B12: 2016 | C12: 1.1.1.3.00.00.00 | D12: Impostos sobre a Produção e a Circulação | E12: 1.1.1.3.00.00.00 - Impostos sobre a Produção e a Circulação | F12: 57300706
A13: Olinda | B13: 2016 | C13: 1.1.1.3.05.00.00 | D13: Imposto sobre Serviços de Qualquer Natureza ¿ ISSQN | E13: 1.1.1.3.05.00.00 - Imposto sobre Serviços de Qualquer Natureza ¿ ISSQN | F13: 57300706
A14: Olinda | B14: 2016 | C14: 1.1.2.0.00.00.00 | D14: Taxas | E14: 1.1.2.0.00.00.00 - Taxas | F14: 20789434
... A2455: Petrolina | B2455: 2025 | C2455: TOTAL DAS RECEITAS (III) = (I + II) | D2455: TOTAL DAS RECEITAS (III) = (I + II) | E2455: TOTAL DAS RECEITAS (III) = (I + II) | F2455: 1.9533483e+09
